Workbook

Sheet ToTal_From PO_6_underway
E1: حسابات أمر الشراء (PO3 ) حسب كميات المستخلص
B2: القطاع الجنوبي | K2: مدة العقد =60 شهر ميلادي | M2: رقم العقد = 101230258
A3: ملخص صرف امر شراء رقم 6
A4: م | B4: الوصف | C4: الوحدة | D4: السعر الافرادي | E4: العقد الاساسي | I4: امر الشراء رقم 6 | K4: إجمالي المستخلصات | M4: المتبقي حسب كميات المستخلص
E5: الكمية | F5: المدة | H5: المبلغ الاجمالي | I5: الكمية | J5: الاجمالي (ريال) | K5: الكمية | L5: الاجمالي (ريال) | M5: الكمية | N5: الاجمالي (ريال)
A6: 1 | B6: مدير المشروع | C6: عدد | D6: 50000 | E6: 1 | F6: 60 | G6: =E6*F6 -> 60 | H6: =E6*F6*D6 -> 3000000 | J6: =I6*D6 -> 0 | K6: ='27_D'!M6+'28'!M6+'29'!M6+'30'!M6+'31'!M6+'32'!M6+'33'!M6+'34'!M6+'35'!M6 -> 7.5324117 | L6: =K6*D6 -> 376620.58
A7: 2 | B7: مهندس مقيم E1 | C7: عدد | D7: 45000 | E7: 1 | F7: 60 | G7: =E7*F7 -> 60 | H7: =E7*F7*D7 -> 2700000 | J7: =I7*D7 -> 0 | K7: ='27_D'!M7+'28'!M7+'29'!M7+'30'!M7+'31'!M7+'32'!M7+'33'!M7+'34'!M7+'35'!M7 -> 0 | L7: =K7*D7 -> 0
A8: 3 | B8: مهندس مقيم E2 | C8: عدد | D8: 23000 | E8: 2 | F8: 60 | G8: =E8*F8 -> 120 | H8: =E8*F8*D8 -> 2760000 | J8: =I8*D8 -> 0 | K8: ='27_D'!M8+'28'!M8+'29'!M8+'30'!M8+'31'!M8+'32'!M8+'33'!M8+'34'!M8+'35'!M8 -> 0 | L8: =K8*D8 -> 0
A9: 4 | B9: مهندس مقيم E3 | C9: عدد | D9: 28000 | E9: 7 | F9: 60 | G9: =E9*F9 -> 420 | H9: =E9*F9*D9 -> 11760000 | J9: =I9*D9 -> 0 | K9: ='27_D'!M9+'28'!M9+'29'!M9+'30'!M9+'31'!M9+'32'!M9+'33'!M9+'34'!M9+'35'!M9 -> 251.84562 | L9: =K9*D9 -> 7051677.4
A10: 5 | B10: مهندس موقع E2 | C10: عدد | D10: 19000 | E10: 3 | F10: 60 | G10: =E10*F10 -> 180 | H10: =E10*F10*D10 -> 3420000 | J10: =I10*D10 -> 0 | K10: ='27_D'!M10+'28'!M10+'29'!M10+'30'!M10+'31'!M10+'32'!M10+'33'!M10+'34'!M10+'35'!M10 -> 19.677573 | L10: =K10*D10 -> 373873.89
A11: 6 | B11: مهندس موقع E3 | C11: عدد | D11: 21000 | E11: 15 | F11: 60 | G11: =E11*F11 -> 900 | H11: =E11*F11*D11 -> 18900000 | J11: =I11*D11 -> 0 | K11: ='27_D'!M11+'28'!M11+'29'!M11+'30'!M11+'31'!M11+'32'!M11+'33'!M11+'34'!M11+'35'!M11 -> 490.76167 | L11: =K11*D11 -> 10305995
A12: 7 | B12: مهندس ميكانيكا E2 | C12: عدد | D12: 19000 | E12: 2 | F12: 60 | G12: =E12*F12 -> 120 | H12: =E12*F12*D12 -> 2280000 | J12: =I12*D12 -> 0 | K12: ='27_D'!M12+'28'!M12+'29'!M12+'30'!M12+'31'!M12+'32'!M12+'33'!M12+'34'!M12+'35'!M12 -> 9 | L12: =K12*D12 -> 171000
A13: 8 | B13: مهندس ميكانيكا E3 | C13: عدد | D13: 21000 | E13: 6 | F13: 60 | G13: =E13*F13 -> 360 | H13: =E13*F13*D13 -> 7560000 | J13: =I13*D13 -> 0 | K13: ='27_D'!M13+'28'!M13+'29'!M13+'30'!M13+'31'!M13+'32'!M13+'33'!M13+'34'!M13+'35'!M13 -> 116.0437 | L13: =K13*D13 -> 2436917.7
A14: 9 | B14: مهندس كهرباء وتحكم E2 | C14: عدد | D14: 19000 | E14: 2 | F14: 60 | G14: =E14*F14 -> 120 | H14: =E14*F14*D14 -> 2280000 | J14: =I14*D14 -> 0 | K14: ='27_D'!M14+'28'!M14+'29'!M14+'30'!M14+'31'!M14+'32'!M14+'33'!M14+'34'!M14+'35'!M14 -> 8.483871 | L14: =K14*D14 -> 161193.55
A15: 10 | B15: مهندس كهرباء وتحكم E3 | C15: عدد | D15: 21000 | E15: 5 | F15: 60 | G15: =E15*F15 -> 300 | H15: =E15*F15*D15 -> 6300000 | J15: =I15*D15 -> 0 | K15: ='27_D'!M15+'28'!M15+'29'!M15+'30'!M15+'31'!M15+'32'!M15+'33'!M15+'34'!M15+'35'!M15 -> 132.14639 | L15: =K15*D15 -> 2775074.2
A16: 11 | B16: مهندس أمن وسلامة E2 | C16: عدد | D16: 18000 | E16: 2 | F16: 60 | G16: =E16*F16 -> 120 | H16: =E16*F16*D16 -> 2160000 | J16: =I16*D16 -> 0 | K16: ='27_D'!M16+'28'!M16+'29'!M16+'30'!M16+'31'!M16+'32'!M16+'33'!M16+'34'!M16+'35'!M16 -> 26.166667 | L16: =K16*D16 -> 471000
A17: 12 | B17: مهندس أمن وسلامة E3 | C17: عدد | D17: 21000 | E17: 5 | F17: 60 | G17: =E17*F17 -> 300 | H17: =E17*F17*D17 -> 6300000 | J17: =I17*D17 -> 0 | K17: ='27_D'!M17+'28'!M17+'29'!M17+'30'!M17+'31'!M17+'32'!M17+'33'!M17+'34'!M17+'35'!M17 -> 88.427266 | L17: =K17*D17 -> 1856972.6
... A25: 20 | B25: مهندس كيميائي E3 | C25: عدد | D25: 23000 | E25: 1 | F25: 60 | G25: =E25*F25 -> 60 | H25: =E25*F25*D25 -> 1380000 | J25: =I25*D25 -> 0 | K25: ='27_D'!M25+'28'!M25+'29'!M25+'30'!M25+'31'!M25+'32'!M25+'33'!M25+'34'!M25+'35'!M25 -> 0 | L25: =K25*D25 -> 0
A26: 21 | B26: حاسب كميات E2 | C26: عدد | D26: 15000 | E26: 1 | F26: 60 | H26: =E26*F26*D26 -> 900000 | J26: =I26*D26 -> 0 | K26: ='27_D'!M26+'28'!M26+'29'!M26+'30'!M26+'31'!M26+'32'!M26+'33'!M26+'34'!M26+'35'!M26 -> 57.473041 | L26: =K26*D26 -> 862095.62
A27: 22 | B27: حاسب كميات E3 | C27: عدد | D27: 17000 | E27: 2 | F27: 60 | H27: =E27*F27*D27 -> 2040000 | J27: =I27*D27 -> 0 | K27: ='27_D'!M27+'28'!M27+'29'!M27+'30'!M27+'31'!M27+'32'!M27+'33'!M27+'34'!M27+'35'!M27 -> 204.29009 | L27: =K27*D27 -> 3472931.6
A28: 23 | B28: مراقب موقع E2 | C28: عدد | D28: 12000 | E28: 7 | F28: 60 | H28: =E28*F28*D28 -> 5040000 | J28: =I28*D28 -> 0 | K28: ='27_D'!M28+'28'!M28+'29'!M28+'30'!M28+'31'!M28+'32'!M28+'33'!M28+'34'!M28+'35'!M28 -> 166.37381 | L28: =K28*D28 -> 1996485.7
A29: 24 | B29: مراقب موقع E3 | C29: عدد | D29: 12000 | E29: 25 | F29: 60 | G29: =E29*F29 -> 1500 | H29: =E29*F29*D29 -> 18000000 | J29: =I29*D29 -> 0 | K29: ='27_D'!M29+'28'!M29+'29'!M29+'30'!M29+'31'!M29+'32'!M29+'33'!M29+'34'!M29+'35'!M29 -> 816.6914 | L29: =K29*D29 -> 9800296.8
A30: 25 | B30: مساح E2 | C30: عدد | D30: 11000 | E30: 2 | F30: 60 | H30: =E30*F30*D30 -> 1320000 | J30: =I30*D30 -> 0 | K30: ='27_D'!M30+'28'!M30+'29'!M30+'30'!M30+'31'!M30+'32'!M30+'33'!M30+'34'!M30+'35'!M30 -> 29.472811 | L30: =K30*D30 -> 324200.92
A31: 26 | B31: مساح E3 | C31: عدد | D31: 13000 | E31: 7 | F31: 60 | H31: =E31*F31*D31 -> 5460000 | J31: =I31*D31 -> 0 | K31: ='27_D'!M31+'28'!M31+'29'!M31+'30'!M31+'31'!M31+'32'!M31+'33'!M31+'34'!M31+'35'!M31 -> 714.29147 | L31: =K31*D31 -> 9285789.2
A32: 27 | B32: مراقب أمن وسلامة E2 | C32: عدد | D32: 11000 | E32: 2 | F32: 60 | H32: =E32*F32*D32 -> 1320000 | J32: =I32*D32 -> 0 | K32: ='27_D'!M32+'28'!M32+'29'!M32+'30'!M32+'31'!M32+'32'!M32+'33'!M32+'34'!M32+'35'!M32 -> 230.82542 | L32: =K32*D32 -> 2539079.6
A33: 28 | B33: مراقب أمن وسلامة E3 | C33: عدد | D33: 12000 | E33: 8 | F33: 60 | H33: =E33*F33*D33 -> 5760000 | J33: =I33*D33 -> 0 | K33: ='27_D'!M33+'28'!M33+'29'!M33+'30'!M33+'31'!M33+'32'!M33+'33'!M33+'34'!M33+'35'!M33 -> 297.16559 | L33: =K33*D33 -> 3565987.1
A34: 29 | B34: أخصائي وثائق E2 | C34: عدد | D34: 10000 | E34: 1 | F34: 60 | G34: =E34*F34 -> 60 | H34: =E34*F34*D34 -> 600000 | J34: =I34*D34 -> 0 | K34: ='27_D'!M34+'28'!M34+'29'!M34+'30'!M34+'31'!M34+'32'!M34+'33'!M34+'34'!M34+'35'!M34 -> 191.33149 | L34: =K34*D34 -> 1913314.9
A35: 30 | B35: أخصائي وثائق E3 | C35: عدد | D35: 10000 | E35: 3 | F35: 60 | G35: =E35*F35 -> 180 | H35: =E35*F35*D35 -> 1800000 | J35: =I35*D35 -> 0 | K35: ='27_D'!M35+'28'!M35+'29'!M35+'30'!M35+'31'!M35+'32'!M35+'33'!M35+'34'!M35+'35'!M35 -> 119.85353 | L35: =K35*D35 -> 1198535.3
A36: الإجمـــــــــــــــــــــــــــــالي | E36: =SUM(E6:E35) -> 118 | G36: =SUM(G6:G35) -> 5340 | H36: =SUM(H6:H35) -> 126000000 | J36: =SUM(J6:J35) -> 0 | L36: =SUM(L6:L35) -> 62850445 | N36: =SUM(N6:N35) -> 0
A37: قيمة الضريبة المضافة | H37: =H36*0.15 -> 18900000 | J37: =J36*0.15 -> 0 | L37: =L36*0.15 -> 9427566.8 | N37: =N36*0.15 -> 0
A38: الإجمـــــــــــــــــــــــــــــالي بعد اضافة 15% قيمة مضافة | H38: =H36+H37 -> 144900000 | J38: =J36+J37 -> 0 | L38: =L36+L37 -> 72278012 | N38: =N36+N37 -> 0
A39: نسبة المستحق لاجمالي العقد | J39: =J36/H36 -> 0 | L39: 0.23952879 | N39: =N36/H36 -> 0

Sheet 35
I1: ملخص المستخلص رقم (33)
B2: القطاع الجنوبي | I2: عن الفترة مـن 2026/5/01م حتى 2026/5/31 | O2: مدة العقد =60 شهر ميلادي | Q2: رقم العقد = 101230258
C3: مشروع : إتفاقية الخدمات الهندسية والإستشارية لتقديم خدمات الإشراف على تنفيذ مشاريع المياه والصرف الصحي بالقطاع الجنوبي | O3: قيمة العقد الأساسية = 126,000,000 ريال | Q3: قيمة العقد المعدلة المعتمدة = 305,111,979 ريال
A4: م | B4: الوصف | C4: الوحدة | D4: السعر الافرادي | E4: العقد الاساسي | I4: الجدول المعدل رقم (1) | M4: المستحق عن الفترة | O4: السابق | Q4: الاجمالي
E5: الكمية | F5: المدة | H5: المبلغ الاجمالي | I5: الكمية | J5: المدة | L5: المبلغ الاجمالي | M5: المدة الاجمالية لفترة المستحلص | N5: المبلغ الاجمالي لفترة المستخلص | O5: المدة الاجمالية السابقة (شهر) | P5: المبلغ الاجمالي السابق | Q5: اجمالي المدة | R5: المبلغ الاجمالي
A6: 1 | B6: مدير المشروع | C6: عدد | D6: 50000 | E6: 1 | F6: 60 | G6: 60 | H6: 3000000 | I6: 1.5 | J6: 52.86 | K6: 79.29 | L6: 3964500 | M6: 1 | N6: =D6*M6 -> 50000 | O6: 43.331336 | P6: 2166566.8 | Q6: =M6+O6 -> 44.331336 | R6: =P6+N6 -> 2216566.8
A7: 2 | B7: مهندس مقيم E1 | C7: عدد | D7: 45000 | E7: 1 | F7: 60 | G7: 60 | H7: 2700000 | I7: 0 | J7: 52.86 | K7: 0 | L7: 0 | M7: 0 | N7: =D7*M7 -> 0 | O7: 0 | P7: 0 | Q7: =M7+O7 -> 0 | R7: =P7+N7 -> 0
A8: 3 | B8: مهندس مقيم E2 | C8: عدد | D8: 23000 | E8: 2 | F8: 60 | G8: 120 | H8: 2760000 | I8: 0 | J8: 52.86 | K8: 0 | L8: 0 | M8: 0 | N8: =D8*M8 -> 0 | O8: 0 | P8: 0 | Q8: =M8+O8 -> 0 | R8: =P8+N8 -> 0
A9: 4 | B9: مهندس مقيم E3 | C9: عدد | D9: 28000 | E9: 7 | F9: 60 | G9: 420 | H9: 11760000 | I9: 23 | J9: 52.86 | K9: 1215.78 | L9: 34041840 | M9: 26.806452 | N9: =D9*M9 -> 750580.65 | O9: 817.63723 | P9: 22893842 | Q9: =M9+O9 -> 844.44368 | R9: =P9+N9 -> 23644423
A10: 5 | B10: مهندس موقع E2 | C10: عدد | D10: 19000 | E10: 3 | F10: 60 | G10: 180 | H10: 3420000 | I10: 4 | J10: 52.86 | K10: 211.44 | L10: 4017360 | M10: 0 | N10: =D10*M10 -> 0 | O10: 56.591656 | P10: 1075241.5 | Q10: =M10+O10 -> 56.591656 | R10: =P10+N10 -> 1075241.5
A11: 6 | B11: مهندس موقع E3 | C11: عدد | D11: 21000 | E11: 15 | F11: 60 | G11: 900 | H11: 18900000 | I11: 47 | J11: 52.86 | K11: 2484.42 | L11: 52172820 | M11: 56.935484 | N11: =D11*M11 -> 1195645.2 | O11: 1539.2201 | P11: 32323622 | Q11: =M11+O11 -> 1596.1556 | R11: =P11+N11 -> 33519268
A12: 7 | B12: مهندس ميكانيكا E2 | C12: عدد | D12: 19000 | E12: 2 | F12: 60 | G12: 120 | H12: 2280000 | I12: 3 | J12: 52.86 | K12: 158.58 | L12: 3013020 | M12: 1 | N12: =D12*M12 -> 19000 | O12: 34.146633 | P12: 648786.03 | Q12: =M12+O12 -> 35.146633 | R12: =P12+N12 -> 667786.03
A13: 8 | B13: مهندس ميكانيكا E3 | C13: عدد | D13: 21000 | E13: 6 | F13: 60 | G13: 360 | H13: 7560000 | I13: 15 | J13: 52.86 | K13: 792.9 | L13: 16650900 | M13: 13.580645 | N13: =D13*M13 -> 285193.55 | O13: 375.92473 | P13: 7894419.4 | Q13: =M13+O13 -> 389.50538 | R13: =P13+N13 -> 8179613
A14: 9 | B14: مهندس كهرباء وتحكم E2 | C14: عدد | D14: 19000 | E14: 2 | F14: 60 | G14: 120 | H14: 2280000 | I14: 3 | J14: 52.86 | K14: 158.58 | L14: 3013020 | M14: 0.80645161 | N14: =D14*M14 -> 15322.581 | O14: 28.51172 | P14: 541722.69 | Q14: =M14+O14 -> 29.318172 | R14: =P14+N14 -> 557045.27
A15: 10 | B15: مهندس كهرباء وتحكم E3 | C15: عدد | D15: 21000 | E15: 5 | F15: 60 | G15: 300 | H15: 6300000 | I15: 14 | J15: 52.86 | K15: 740.04 | L15: 15540840 | M15: 15 | N15: =D15*M15 -> 315000 | O15: 338.84738 | P15: 7115795 | Q15: =M15+O15 -> 353.84738 | R15: =P15+N15 -> 7430795
A16: 11 | B16: مهندس أمن وسلامة E2 | C16: عدد | D16: 18000 | E16: 2 | F16: 60 | G16: 120 | H16: 2160000 | I16: 4 | J16: 52.86 | K16: 211.44 | L16: 3805920 | M16: 3 | N16: =D16*M16 -> 54000 | O16: 118.09944 | P16: 2125789.9 | Q16: =M16+O16 -> 121.09944 | R16: =P16+N16 -> 2179789.9
A17: 12 | B17: مهندس أمن وسلامة E3 | C17: عدد | D17: 21000 | E17: 5 | F17: 60 | G17: 300 | H17: 6300000 | I17: 11 | J17: 52.86 | K17: 581.46 | L17: 12210660 | M17: 9 | N17: =D17*M17 -> 189000 | O17: 249.62118 | P17: 5242044.8 | Q17: =M17+O17 -> 258.62118 | R17: =P17+N17 -> 5431044.8
... A25: 20 | B25: مهندس كيميائي E3 | C25: عدد | D25: 23000 | E25: 1 | F25: 60 | G25: 60 | H25: 1380000 | I25: 0 | J25: 52.86 | K25: 0 | L25: 0 | M25: 0 | N25: =D25*M25 -> 0 | O25: 0 | P25: 0 | Q25: =M25+O25 -> 0 | R25: =P25+N25 -> 0
A26: 21 | B26: حاسب كميات E2 | C26: عدد | D26: 15000 | E26: 1 | F26: 60 | H26: 900000 | I26: 4 | J26: 52.86 | L26: 3171600 | M26: 4 | N26: =D26*M26 -> 60000 | O26: 208.82718 | P26: 3132407.7 | Q26: =M26+O26 -> 212.82718 | R26: =P26+N26 -> 3192407.7
A27: 22 | B27: حاسب كميات E3 | C27: عدد | D27: 17000 | E27: 2 | F27: 60 | H27: 2040000 | I27: 14 | J27: 52.86 | L27: 12580680 | M27: 21.129032 | N27: =D27*M27 -> 359193.55 | O27: 505.31017 | P27: 8590272.8 | Q27: =M27+O27 -> 526.4392 | R27: =P27+N27 -> 8949466.4
A28: 23 | B28: مراقب موقع E2 | C28: عدد | D28: 12000 | E28: 7 | F28: 60 | H28: 5040000 | I28: 16 | J28: 52.86 | L28: 10149120 | M28: 12.774194 | N28: =D28*M28 -> 153290.32 | O28: 591.5884 | P28: 7099060.8 | Q28: =M28+O28 -> 604.36259 | R28: =P28+N28 -> 7252351.1
A29: 24 | B29: مراقب موقع E3 | C29: عدد | D29: 12000 | E29: 25 | F29: 60 | G29: 1500 | H29: 18000000 | I29: 74 | J29: 52.86 | K29: 3911.64 | L29: 46939680 | M29: 84.645161 | N29: =D29*M29 -> 1015741.9 | O29: 2117.7857 | P29: 25413428 | Q29: =M29+O29 -> 2202.4308 | R29: =P29+N29 -> 26429170
A30: 25 | B30: مساح E2 | C30: عدد | D30: 11000 | E30: 2 | F30: 60 | H30: 1320000 | I30: 4 | J30: 52.86 | L30: 2325840 | M30: 3 | N30: =D30*M30 -> 33000 | O30: 113.2445 | P30: 1245689.6 | Q30: =M30+O30 -> 116.2445 | R30: =P30+N30 -> 1278689.6
A31: 26 | B31: مساح E3 | C31: عدد | D31: 13000 | E31: 7 | F31: 60 | H31: 5460000 | I31: 50 | J31: 52.86 | L31: 34359000 | M31: 77.16129 | N31: =D31*M31 -> 1003096.8 | O31: 1919.7238 | P31: 24956409 | Q31: =M31+O31 -> 1996.8851 | R31: =P31+N31 -> 25959506
A32: 27 | B32: مراقب أمن وسلامة E2 | C32: عدد | D32: 11000 | E32: 2 | F32: 60 | H32: 1320000 | I32: 16 | J32: 52.86 | L32: 9303360 | M32: 27.870968 | N32: =D32*M32 -> 306580.65 | O32: 617.00447 | P32: 6787049.1 | Q32: =M32+O32 -> 644.87543 | R32: =P32+N32 -> 7093629.8
A33: 28 | B33: مراقب أمن وسلامة E3 | C33: عدد | D33: 12000 | E33: 8 | F33: 60 | H33: 5760000 | I33: 26 | J33: 52.86 | L33: 16492320 | M33: 33.903226 | N33: =D33*M33 -> 406838.71 | O33: 653.54237 | P33: 7842508.4 | Q33: =M33+O33 -> 687.44559 | R33: =P33+N33 -> 8249347.1
A34: 29 | B34: أخصائي وثائق E2 | C34: عدد | D34: 10000 | E34: 1 | F34: 60 | G34: 60 | H34: 600000 | I34: 10 | J34: 52.86 | K34: 528.6 | L34: 5286000 | M34: 13.677419 | N34: =D34*M34 -> 136774.19 | O34: 606.57826 | P34: 6065782.6 | Q34: =M34+O34 -> 620.25568 | R34: =P34+N34 -> 6202556.8
A35: 30 | B35: أخصائي وثائق E3 | C35: عدد | D35: 10000 | E35: 3 | F35: 60 | G35: 180 | H35: 1800000 | I35: 9.4076788 | J35: 52.86 | K35: 497.2899 | L35: 4972899 | M35: 13.903226 | N35: =D35*M35 -> 139032.26 | O35: 374.70415 | P35: 3747041.5 | Q35: =M35+O35 -> 388.60737 | R35: =P35+N35 -> 3886073.7
A36: الإجمـــــــــــــــــــــــــــــالي | H36: =SUM(H6:H35) -> 126000000 | K36: =SUM(K6:K35) -> 12047.2 | L36: =SUM(L6:L35) -> 305111979 | N36: =SUM(N6:N35) -> 6697290.3 | P36: =SUM(P6:P35) -> 1.8208664e+08 | R36: =SUM(R6:R35) -> 1.8878393e+08
A37: قيمة الضريبة المضافة | L37: =L36*0.15 -> 45766797 | N37: =N36*0.15 -> 1004593.5 | P37: =P36*0.15 -> 27312995 | R37: =R36*0.15 -> 28317589
A38: الإجمـــــــــــــــــــــــــــــالي بعد اضافة 15% قيمة مضافة | L38: =L36+L37 -> 3.5087878e+08 | N38: =N36+N37 -> 7701883.9 | P38: =P36+P37 -> 2.0939963e+08 | R38: =R36+R37 -> 2.1710152e+08
A39: نسبة المستحق لاجمالي العقد | N39: =N36/L36 -> 0.02195027 | P39: 0.23952879 | R39: =R36/L36 -> 0.61873653

Sheet 34
C1: ملخص المستخلص رقم (34)
B2: القطاع الجنوبي | I2: عن الفترة مـن 2026/6/01م حتى 2026/6/30 | O2: مدة العقد =60 شهر ميلادي | Q2: رقم العقد = 101230258
C3: مشروع : إتفاقية الخدمات الهندسية والإستشارية لتقديم خدمات الإشراف على تنفيذ مشاريع المياه والصرف الصحي بالقطاع الجنوبي | O3: قيمة العقد الأساسية = 126,000,000 ريال | Q3: قيمة العقد المعدلة المعتمدة = 305,111,979 ريال
A4: م | B4: الوصف | C4: الوحدة | D4: السعر الافرادي | E4: العقد الاساسي | I4: الجدول المعدل رقم (1) | M4: المستحق عن الفترة | O4: السابق | Q4: الاجمالي
E5: الكمية | F5: المدة | H5: المبلغ الاجمالي | I5: الكمية | J5: المدة | L5: المبلغ الاجمالي | M5: المدة الاجمالية لفترة المستحلص | N5: المبلغ الاجمالي لفترة المستخلص | O5: المدة الاجمالية السابقة (شهر) | P5: المبلغ الاجمالي السابق | Q5: اجمالي المدة | R5: المبلغ الاجمالي
A6: 1 | B6: مدير المشروع | C6: عدد | D6: 50000 | E6: 1 | F6: 60 | G6: 60 | H6: 3000000 | I6: 1.5 | J6: 52.86 | K6: 79.29 | L6: 3964500 | M6: 1 | N6: =D6*M6 -> 50000 | O6: 42.331336 | P6: 2116566.8 | Q6: =M6+O6 -> 43.331336 | R6: =P6+N6 -> 2166566.8
A7: 2 | B7: مهندس مقيم E1 | C7: عدد | D7: 45000 | E7: 1 | F7: 60 | G7: 60 | H7: 2700000 | I7: 0 | J7: 52.86 | K7: 0 | L7: 0 | M7: 0 | N7: =D7*M7 -> 0 | O7: 0 | P7: 0 | Q7: =M7+O7 -> 0 | R7: =P7+N7 -> 0
A8: 3 | B8: مهندس مقيم E2 | C8: عدد | D8: 23000 | E8: 2 | F8: 60 | G8: 120 | H8: 2760000 | I8: 0 | J8: 52.86 | K8: 0 | L8: 0 | M8: 0 | N8: =D8*M8 -> 0 | O8: 0 | P8: 0 | Q8: =M8+O8 -> 0 | R8: =P8+N8 -> 0
A9: 4 | B9: مهندس مقيم E3 | C9: عدد | D9: 28000 | E9: 7 | F9: 60 | G9: 420 | H9: 11760000 | I9: 23 | J9: 52.86 | K9: 1215.78 | L9: 34041840 | M9: 28.033333 | N9: =D9*M9 -> 784933.33 | O9: 789.60389 | P9: 22108909 | Q9: =M9+O9 -> 817.63723 | R9: =P9+N9 -> 22893842
A10: 5 | B10: مهندس موقع E2 | C10: عدد | D10: 19000 | E10: 3 | F10: 60 | G10: 180 | H10: 3420000 | I10: 4 | J10: 52.86 | K10: 211.44 | L10: 4017360 | M10: 0 | N10: =D10*M10 -> 0 | O10: 56.591656 | P10: 1075241.5 | Q10: =M10+O10 -> 56.591656 | R10: =P10+N10 -> 1075241.5
A11: 6 | B11: مهندس موقع E3 | C11: عدد | D11: 21000 | E11: 15 | F11: 60 | G11: 900 | H11: 18900000 | I11: 47 | J11: 52.86 | K11: 2484.42 | L11: 52172820 | M11: 55.366667 | N11: =D11*M11 -> 1162700 | O11: 1483.8535 | P11: 31160922 | Q11: =M11+O11 -> 1539.2201 | R11: =P11+N11 -> 32323622
A12: 7 | B12: مهندس ميكانيكا E2 | C12: عدد | D12: 19000 | E12: 2 | F12: 60 | G12: 120 | H12: 2280000 | I12: 3 | J12: 52.86 | K12: 158.58 | L12: 3013020 | M12: 1 | N12: =D12*M12 -> 19000 | O12: 33.146633 | P12: 629786.03 | Q12: =M12+O12 -> 34.146633 | R12: =P12+N12 -> 648786.03
A13: 8 | B13: مهندس ميكانيكا E3 | C13: عدد | D13: 21000 | E13: 6 | F13: 60 | G13: 360 | H13: 7560000 | I13: 15 | J13: 52.86 | K13: 792.9 | L13: 16650900 | M13: 13.566667 | N13: =D13*M13 -> 284900 | O13: 362.35807 | P13: 7609519.4 | Q13: =M13+O13 -> 375.92473 | R13: =P13+N13 -> 7894419.4
A14: 9 | B14: مهندس كهرباء وتحكم E2 | C14: عدد | D14: 19000 | E14: 2 | F14: 60 | G14: 120 | H14: 2280000 | I14: 3 | J14: 52.86 | K14: 158.58 | L14: 3013020 | M14: 1 | N14: =D14*M14 -> 19000 | O14: 27.51172 | P14: 522722.69 | Q14: =M14+O14 -> 28.51172 | R14: =P14+N14 -> 541722.69
A15: 10 | B15: مهندس كهرباء وتحكم E3 | C15: عدد | D15: 21000 | E15: 5 | F15: 60 | G15: 300 | H15: 6300000 | I15: 14 | J15: 52.86 | K15: 740.04 | L15: 15540840 | M15: 13.766667 | N15: =D15*M15 -> 289100 | O15: 325.08072 | P15: 6826695 | Q15: =M15+O15 -> 338.84738 | R15: =P15+N15 -> 7115795
A16: 11 | B16: مهندس أمن وسلامة E2 | C16: عدد | D16: 18000 | E16: 2 | F16: 60 | G16: 120 | H16: 2160000 | I16: 4 | J16: 52.86 | K16: 211.44 | L16: 3805920 | M16: 3 | N16: =D16*M16 -> 54000 | O16: 115.09944 | P16: 2071789.9 | Q16: =M16+O16 -> 118.09944 | R16: =P16+N16 -> 2125789.9
A17: 12 | B17: مهندس أمن وسلامة E3 | C17: عدد | D17: 21000 | E17: 5 | F17: 60 | G17: 300 | H17: 6300000 | I17: 11 | J17: 52.86 | K17: 581.46 | L17: 12210660 | M17: 9.7 | N17: =D17*M17 -> 203700 | O17: 239.92118 | P17: 5038344.8 | Q17: =M17+O17 -> 249.62118 | R17: =P17+N17 -> 5242044.8
... A25: 20 | B25: مهندس كيميائي E3 | C25: عدد | D25: 23000 | E25: 1 | F25: 60 | G25: 60 | H25: 1380000 | I25: 0 | J25: 52.86 | K25: 0 | L25: 0 | M25: 0 | N25: =D25*M25 -> 0 | O25: 0 | P25: 0 | Q25: =M25+O25 -> 0 | R25: =P25+N25 -> 0
A26: 21 | B26: حاسب كميات E2 | C26: عدد | D26: 15000 | E26: 1 | F26: 60 | H26: 900000 | I26: 4 | J26: 52.86 | L26: 3171600 | M26: 4 | N26: =D26*M26 -> 60000 | O26: 204.82718 | P26: 3072407.7 | Q26: =M26+O26 -> 208.82718 | R26: =P26+N26 -> 3132407.7
A27: 22 | B27: حاسب كميات E3 | C27: عدد | D27: 17000 | E27: 2 | F27: 60 | H27: 2040000 | I27: 14 | J27: 52.86 | L27: 12580680 | M27: 20.366667 | N27: =D27*M27 -> 346233.33 | O27: 484.9435 | P27: 8244039.5 | Q27: =M27+O27 -> 505.31017 | R27: =P27+N27 -> 8590272.8
A28: 23 | B28: مراقب موقع E2 | C28: عدد | D28: 12000 | E28: 7 | F28: 60 | H28: 5040000 | I28: 16 | J28: 52.86 | L28: 10149120 | M28: 11.366667 | N28: =D28*M28 -> 136400 | O28: 580.22173 | P28: 6962660.8 | Q28: =M28+O28 -> 591.5884 | R28: =P28+N28 -> 7099060.8
A29: 24 | B29: مراقب موقع E3 | C29: عدد | D29: 12000 | E29: 25 | F29: 60 | G29: 1500 | H29: 18000000 | I29: 74 | J29: 52.86 | K29: 3911.64 | L29: 46939680 | M29: 77.766667 | N29: =D29*M29 -> 933200 | O29: 2040.019 | P29: 24480228 | Q29: =M29+O29 -> 2117.7857 | R29: =P29+N29 -> 25413428
A30: 25 | B30: مساح E2 | C30: عدد | D30: 11000 | E30: 2 | F30: 60 | H30: 1320000 | I30: 4 | J30: 52.86 | L30: 2325840 | M30: 2.5 | N30: =D30*M30 -> 27500 | O30: 110.7445 | P30: 1218189.6 | Q30: =M30+O30 -> 113.2445 | R30: =P30+N30 -> 1245689.6
A31: 26 | B31: مساح E3 | C31: عدد | D31: 13000 | E31: 7 | F31: 60 | H31: 5460000 | I31: 50 | J31: 52.86 | L31: 34359000 | M31: 74.833333 | N31: =D31*M31 -> 972833.33 | O31: 1844.8905 | P31: 23983576 | Q31: =M31+O31 -> 1919.7238 | R31: =P31+N31 -> 24956409
A32: 27 | B32: مراقب أمن وسلامة E2 | C32: عدد | D32: 11000 | E32: 2 | F32: 60 | H32: 1320000 | I32: 16 | J32: 52.86 | L32: 9303360 | M32: 25.866667 | N32: =D32*M32 -> 284533.33 | O32: 591.1378 | P32: 6502515.8 | Q32: =M32+O32 -> 617.00447 | R32: =P32+N32 -> 6787049.1
A33: 28 | B33: مراقب أمن وسلامة E3 | C33: عدد | D33: 12000 | E33: 8 | F33: 60 | H33: 5760000 | I33: 26 | J33: 52.86 | L33: 16492320 | M33: 32.333333 | N33: =D33*M33 -> 388000 | O33: 621.20903 | P33: 7454508.4 | Q33: =M33+O33 -> 653.54237 | R33: =P33+N33 -> 7842508.4
A34: 29 | B34: أخصائي وثائق E2 | C34: عدد | D34: 10000 | E34: 1 | F34: 60 | G34: 60 | H34: 600000 | I34: 10 | J34: 52.86 | K34: 528.6 | L34: 5286000 | M34: 12.7 | N34: =D34*M34 -> 127000 | O34: 593.87826 | P34: 5938782.6 | Q34: =M34+O34 -> 606.57826 | R34: =P34+N34 -> 6065782.6
A35: 30 | B35: أخصائي وثائق E3 | C35: عدد | D35: 10000 | E35: 3 | F35: 60 | G35: 180 | H35: 1800000 | I35: 9.4076788 | J35: 52.86 | K35: 497.2899 | L35: 4972899 | M35: 12.233333 | N35: =D35*M35 -> 122333.33 | O35: 362.47081 | P35: 3624708.1 | Q35: =M35+O35 -> 374.70415 | R35: =P35+N35 -> 3747041.5
A36: الإجمـــــــــــــــــــــــــــــالي | H36: =SUM(H6:H35) -> 126000000 | K36: =SUM(K6:K35) -> 12047.2 | L36: =SUM(L6:L35) -> 305111979 | N36: =SUM(N6:N35) -> 6473266.7 | P36: =SUM(P6:P35) -> 1.7561337e+08 | R36: =SUM(R6:R35) -> 1.8208664e+08
A37: قيمة الضريبة المضافة | L37: =L36*0.15 -> 45766797 | N37: =N36*0.15 -> 970990 | P37: =P36*0.15 -> 26342005 | R37: =R36*0.15 -> 27312995
A38: الإجمـــــــــــــــــــــــــــــالي بعد اضافة 15% قيمة مضافة | L38: =L36+L37 -> 3.5087878e+08 | N38: =N36+N37 -> 7444256.7 | P38: =P36+P37 -> 2.0195537e+08 | R38: =R36+R37 -> 2.0939963e+08
A39: نسبة المستحق لاجمالي العقد | N39: =N36/L36 -> 0.021216036 | P39: 0.23952879 | R39: =R36/L36 -> 0.59678626

Sheet 33
E1: ملخص المستخلص رقم (33)
B2: القطاع الجنوبي | E2: عن الفترة مـن 2026/5/01م حتى 2026/5/31 | O2: مدة العقد =60 شهر ميلادي | Q2: رقم العقد = 101230258
C3: مشروع : إتفاقية الخدمات الهندسية والإستشارية لتقديم خدمات الإشراف على تنفيذ مشاريع المياه والصرف الصحي بالقطاع الجنوبي | O3: قيمة العقد الأساسية = 126,000,000 ريال | Q3: قيمة العقد المعدلة المعتمدة = 305,111,979 ريال
A4: م | B4: الوصف | C4: الوحدة | D4: السعر الافرادي | E4: العقد الاساسي | I4: الجدول المعدل رقم (1) | M4: المستحق عن الفترة | O4: السابق | Q4: الاجمالي
E5: الكمية | F5: المدة | H5: المبلغ الاجمالي | I5: الكمية | J5: المدة | L5: المبلغ الاجمالي | M5: المدة الاجمالية لفترة المستحلص | N5: المبلغ الاجمالي لفترة المستخلص | O5: المدة الاجمالية السابقة (شهر) | P5: المبلغ الاجمالي السابق | Q5: اجمالي المدة | R5: المبلغ الاجمالي
A6: 1 | B6: مدير المشروع | C6: عدد | D6: 50000 | E6: 1 | F6: 60 | G6: 60 | H6: 3000000 | I6: 1.5 | J6: 52.86 | K6: 79.29 | L6: 3964500 | M6: 1 | N6: =D6*M6 -> 50000 | O6: 41.331336 | P6: 2066566.8 | Q6: =M6+O6 -> 42.331336 | R6: =P6+N6 -> 2116566.8
A7: 2 | B7: مهندس مقيم E1 | C7: عدد | D7: 45000 | E7: 1 | F7: 60 | G7: 60 | H7: 2700000 | I7: 0 | J7: 52.86 | K7: 0 | L7: 0 | M7: 0 | N7: =D7*M7 -> 0 | O7: 0 | P7: 0 | Q7: =M7+O7 -> 0 | R7: =P7+N7 -> 0
A8: 3 | B8: مهندس مقيم E2 | C8: عدد | D8: 23000 | E8: 2 | F8: 60 | G8: 120 | H8: 2760000 | I8: 0 | J8: 52.86 | K8: 0 | L8: 0 | M8: 0 | N8: =D8*M8 -> 0 | O8: 0 | P8: 0 | Q8: =M8+O8 -> 0 | R8: =P8+N8 -> 0
A9: 4 | B9: مهندس مقيم E3 | C9: عدد | D9: 28000 | E9: 7 | F9: 60 | G9: 420 | H9: 11760000 | I9: 23 | J9: 52.86 | K9: 1215.78 | L9: 34041840 | M9: 31.225806 | N9: =D9*M9 -> 874322.58 | O9: 758.37809 | P9: 21234586 | Q9: =M9+O9 -> 789.60389 | R9: =P9+N9 -> 22108909
A10: 5 | B10: مهندس موقع E2 | C10: عدد | D10: 19000 | E10: 3 | F10: 60 | G10: 180 | H10: 3420000 | I10: 4 | J10: 52.86 | K10: 211.44 | L10: 4017360 | M10: 2.516129 | N10: =D10*M10 -> 47806.452 | O10: 54.075527 | P10: 1027435 | Q10: =M10+O10 -> 56.591656 | R10: =P10+N10 -> 1075241.5
A11: 6 | B11: مهندس موقع E3 | C11: عدد | D11: 21000 | E11: 15 | F11: 60 | G11: 900 | H11: 18900000 | I11: 47 | J11: 52.86 | K11: 2484.42 | L11: 52172820 | M11: 59.806452 | N11: =D11*M11 -> 1255935.5 | O11: 1424.047 | P11: 29904987 | Q11: =M11+O11 -> 1483.8535 | R11: =P11+N11 -> 31160922
A12: 7 | B12: مهندس ميكانيكا E2 | C12: عدد | D12: 19000 | E12: 2 | F12: 60 | G12: 120 | H12: 2280000 | I12: 3 | J12: 52.86 | K12: 158.58 | L12: 3013020 | M12: 1 | N12: =D12*M12 -> 19000 | O12: 32.146633 | P12: 610786.03 | Q12: =M12+O12 -> 33.146633 | R12: =P12+N12 -> 629786.03
A13: 8 | B13: مهندس ميكانيكا E3 | C13: عدد | D13: 21000 | E13: 6 | F13: 60 | G13: 360 | H13: 7560000 | I13: 15 | J13: 52.86 | K13: 792.9 | L13: 16650900 | M13: 14.032258 | N13: =D13*M13 -> 294677.42 | O13: 348.32581 | P13: 7314842 | Q13: =M13+O13 -> 362.35807 | R13: =P13+N13 -> 7609519.4
A14: 9 | B14: مهندس كهرباء وتحكم E2 | C14: عدد | D14: 19000 | E14: 2 | F14: 60 | G14: 120 | H14: 2280000 | I14: 3 | J14: 52.86 | K14: 158.58 | L14: 3013020 | M14: 1 | N14: =D14*M14 -> 19000 | O14: 26.51172 | P14: 503722.69 | Q14: =M14+O14 -> 27.51172 | R14: =P14+N14 -> 522722.69
A15: 10 | B15: مهندس كهرباء وتحكم E3 | C15: عدد | D15: 21000 | E15: 5 | F15: 60 | G15: 300 | H15: 6300000 | I15: 14 | J15: 52.86 | K15: 740.04 | L15: 15540840 | M15: 14.774194 | N15: =D15*M15 -> 310258.06 | O15: 310.30652 | P15: 6516437 | Q15: =M15+O15 -> 325.08072 | R15: =P15+N15 -> 6826695
A16: 11 | B16: مهندس أمن وسلامة E2 | C16: عدد | D16: 18000 | E16: 2 | F16: 60 | G16: 120 | H16: 2160000 | I16: 4 | J16: 52.86 | K16: 211.44 | L16: 3805920 | M16: 3 | N16: =D16*M16 -> 54000 | O16: 112.09944 | P16: 2017789.9 | Q16: =M16+O16 -> 115.09944 | R16: =P16+N16 -> 2071789.9
A17: 12 | B17: مهندس أمن وسلامة E3 | C17: عدد | D17: 21000 | E17: 5 | F17: 60 | G17: 300 | H17: 6300000 | I17: 11 | J17: 52.86 | K17: 581.46 | L17: 12210660 | M17: 10.354839 | N17: =D17*M17 -> 217451.61 | O17: 229.56634 | P17: 4820893.2 | Q17: =M17+O17 -> 239.92118 | R17: =P17+N17 -> 5038344.8
... A25: 20 | B25: مهندس كيميائي E3 | C25: عدد | D25: 23000 | E25: 1 | F25: 60 | G25: 60 | H25: 1380000 | I25: 0 | J25: 52.86 | K25: 0 | L25: 0 | M25: 0 | N25: =D25*M25 -> 0 | O25: 0 | P25: 0 | Q25: =M25+O25 -> 0 | R25: =P25+N25 -> 0
A26: 21 | B26: حاسب كميات E2 | C26: عدد | D26: 15000 | E26: 1 | F26: 60 | H26: 900000 | I26: 4 | J26: 52.86 | L26: 3171600 | M26: 5.4516129 | N26: =D26*M26 -> 81774.194 | O26: 199.37556 | P26: 2990633.5 | Q26: =M26+O26 -> 204.82718 | R26: =P26+N26 -> 3072407.7
A27: 22 | B27: حاسب كميات E3 | C27: عدد | D27: 17000 | E27: 2 | F27: 60 | H27: 2040000 | I27: 14 | J27: 52.86 | L27: 12580680 | M27: 23.83871 | N27: =D27*M27 -> 405258.06 | O27: 461.10479 | P27: 7838781.4 | Q27: =M27+O27 -> 484.9435 | R27: =P27+N27 -> 8244039.5
A28: 23 | B28: مراقب موقع E2 | C28: عدد | D28: 12000 | E28: 7 | F28: 60 | H28: 5040000 | I28: 16 | J28: 52.86 | L28: 10149120 | M28: 21.225806 | N28: =D28*M28 -> 254709.68 | O28: 558.99593 | P28: 6707951.1 | Q28: =M28+O28 -> 580.22173 | R28: =P28+N28 -> 6962660.8
A29: 24 | B29: مراقب موقع E3 | C29: عدد | D29: 12000 | E29: 25 | F29: 60 | G29: 1500 | H29: 18000000 | I29: 74 | J29: 52.86 | K29: 3911.64 | L29: 46939680 | M29: 94.322581 | N29: =D29*M29 -> 1131871 | O29: 1945.6964 | P29: 23348357 | Q29: =M29+O29 -> 2040.019 | R29: =P29+N29 -> 24480228
A30: 25 | B30: مساح E2 | C30: عدد | D30: 11000 | E30: 2 | F30: 60 | H30: 1320000 | I30: 4 | J30: 52.86 | L30: 2325840 | M30: 3.8387097 | N30: =D30*M30 -> 42225.806 | O30: 106.9058 | P30: 1175963.7 | Q30: =M30+O30 -> 110.7445 | R30: =P30+N30 -> 1218189.6
A31: 26 | B31: مساح E3 | C31: عدد | D31: 13000 | E31: 7 | F31: 60 | H31: 5460000 | I31: 50 | J31: 52.86 | L31: 34359000 | M31: 86.774194 | N31: =D31*M31 -> 1128064.5 | O31: 1758.1163 | P31: 22855511 | Q31: =M31+O31 -> 1844.8905 | R31: =P31+N31 -> 23983576
A32: 27 | B32: مراقب أمن وسلامة E2 | C32: عدد | D32: 11000 | E32: 2 | F32: 60 | H32: 1320000 | I32: 16 | J32: 52.86 | L32: 9303360 | M32: 24 | N32: =D32*M32 -> 264000 | O32: 567.1378 | P32: 6238515.8 | Q32: =M32+O32 -> 591.1378 | R32: =P32+N32 -> 6502515.8
A33: 28 | B33: مراقب أمن وسلامة E3 | C33: عدد | D33: 12000 | E33: 8 | F33: 60 | H33: 5760000 | I33: 26 | J33: 52.86 | L33: 16492320 | M33: 33.967742 | N33: =D33*M33 -> 407612.9 | O33: 587.24129 | P33: 7046895.5 | Q33: =M33+O33 -> 621.20903 | R33: =P33+N33 -> 7454508.4
A34: 29 | B34: أخصائي وثائق E2 | C34: عدد | D34: 10000 | E34: 1 | F34: 60 | G34: 60 | H34: 600000 | I34: 10 | J34: 52.86 | K34: 528.6 | L34: 5286000 | M34: 23.16129 | N34: =D34*M34 -> 231612.9 | O34: 570.71697 | P34: 5707169.7 | Q34: =M34+O34 -> 593.87826 | R34: =P34+N34 -> 5938782.6
A35: 30 | B35: أخصائي وثائق E3 | C35: عدد | D35: 10000 | E35: 3 | F35: 60 | G35: 180 | H35: 1800000 | I35: 9.4076788 | J35: 52.86 | K35: 497.2899 | L35: 4972899 | M35: 14.806452 | N35: =D35*M35 -> 148064.52 | O35: 347.66436 | P35: 3476643.6 | Q35: =M35+O35 -> 362.47081 | R35: =P35+N35 -> 3624708.1
A36: الإجمـــــــــــــــــــــــــــــالي | H36: =SUM(H6:H35) -> 126000000 | K36: =SUM(K6:K35) -> 12047.2 | L36: =SUM(L6:L35) -> 305111979 | N36: =SUM(N6:N35) -> 7453516.1 | P36: =SUM(P6:P35) -> 1.6815985e+08 | R36: =SUM(R6:R35) -> 1.7561337e+08
A37: قيمة الضريبة المضافة | L37: =L36*0.15 -> 45766797 | N37: =N36*0.15 -> 1118027.4 | P37: =P36*0.15 -> 25223978 | R37: =R36*0.15 -> 26342005
A38: الإجمـــــــــــــــــــــــــــــالي بعد اضافة 15% قيمة مضافة | L38: =L36+L37 -> 3.5087878e+08 | N38: =N36+N37 -> 8571543.5 | P38: =P36+P37 -> 1.9338383e+08 | R38: =R36+R37 -> 2.0195537e+08
A39: نسبة المستحق لاجمالي العقد | N39: =N36/L36 -> 0.024428789 | P39: 0.23952879 | R39: =R36/L36 -> 0.57557022

Sheet 32
D1: ملخص المستخلص رقم (32)
B2: القطاع الجنوبي | D2: عن الفترة مـن 2026/4/01م حتى 2026/4/30 | O2: مدة العقد =60 شهر ميلادي | Q2: رقم العقد = 101230258
C3: مشروع : إتفاقية الخدمات الهندسية والإستشارية لتقديم خدمات الإشراف على تنفيذ مشاريع المياه والصرف الصحي بالقطاع الجنوبي | O3: قيمة العقد الأساسية = 126,000,000 ريال | Q3: قيمة العقد المعدلة المعتمدة = 305,111,979 ريال
A4: م | B4: الوصف | C4: الوحدة | D4: السعر الافرادي | E4: العقد الاساسي | I4: الجدول المعدل رقم (1) | M4: المستحق عن الفترة | O4: السابق | Q4: الاجمالي
E5: الكمية | F5: المدة | H5: المبلغ الاجمالي | I5: الكمية | J5: المدة | L5: المبلغ الاجمالي | M5: المدة الاجمالية لفترة المستحلص | N5: المبلغ الاجمالي لفترة المستخلص | O5: المدة الاجمالية السابقة (شهر) | P5: المبلغ الاجمالي السابق | Q5: اجمالي المدة | R5: المبلغ الاجمالي
A6: 1 | B6: مدير المشروع | C6: عدد | D6: 50000 | E6: 1 | F6: 60 | G6: 60 | H6: 3000000 | I6: 1.5 | J6: 52.86 | K6: 79.29 | L6: 3964500 | M6: 0.93333333 | N6: =D6*M6 -> 46666.667 | O6: 40.398003 | P6: 2019900.2 | Q6: =M6+O6 -> 41.331336 | R6: =P6+N6 -> 2066566.8
A7: 2 | B7: مهندس مقيم E1 | C7: عدد | D7: 45000 | E7: 1 | F7: 60 | G7: 60 | H7: 2700000 | I7: 0 | J7: 52.86 | K7: 0 | L7: 0 | M7: 0 | N7: =D7*M7 -> 0 | O7: 0 | P7: 0 | Q7: =M7+O7 -> 0 | R7: =P7+N7 -> 0
A8: 3 | B8: مهندس مقيم E2 | C8: عدد | D8: 23000 | E8: 2 | F8: 60 | G8: 120 | H8: 2760000 | I8: 0 | J8: 52.86 | K8: 0 | L8: 0 | M8: 0 | N8: =D8*M8 -> 0 | O8: 0 | P8: 0 | Q8: =M8+O8 -> 0 | R8: =P8+N8 -> 0
A9: 4 | B9: مهندس مقيم E3 | C9: عدد | D9: 28000 | E9: 7 | F9: 60 | G9: 420 | H9: 11760000 | I9: 23 | J9: 52.86 | K9: 1215.78 | L9: 34041840 | M9: 30.633333 | N9: =D9*M9 -> 857733.33 | O9: 727.74475 | P9: 20376853 | Q9: =M9+O9 -> 758.37809 | R9: =P9+N9 -> 21234586
A10: 5 | B10: مهندس موقع E2 | C10: عدد | D10: 19000 | E10: 3 | F10: 60 | G10: 180 | H10: 3420000 | I10: 4 | J10: 52.86 | K10: 211.44 | L10: 4017360 | M10: 2.5 | N10: =D10*M10 -> 47500 | O10: 51.575527 | P10: 979935.01 | Q10: =M10+O10 -> 54.075527 | R10: =P10+N10 -> 1027435
A11: 6 | B11: مهندس موقع E3 | C11: عدد | D11: 21000 | E11: 15 | F11: 60 | G11: 900 | H11: 18900000 | I11: 47 | J11: 52.86 | K11: 2484.42 | L11: 52172820 | M11: 61.233333 | N11: =D11*M11 -> 1285900 | O11: 1362.8137 | P11: 28619087 | Q11: =M11+O11 -> 1424.047 | R11: =P11+N11 -> 29904987
A12: 7 | B12: مهندس ميكانيكا E2 | C12: عدد | D12: 19000 | E12: 2 | F12: 60 | G12: 120 | H12: 2280000 | I12: 3 | J12: 52.86 | K12: 158.58 | L12: 3013020 | M12: 1 | N12: =D12*M12 -> 19000 | O12: 31.146633 | P12: 591786.03 | Q12: =M12+O12 -> 32.146633 | R12: =P12+N12 -> 610786.03
A13: 8 | B13: مهندس ميكانيكا E3 | C13: عدد | D13: 21000 | E13: 6 | F13: 60 | G13: 360 | H13: 7560000 | I13: 15 | J13: 52.86 | K13: 792.9 | L13: 16650900 | M13: 14.966667 | N13: =D13*M13 -> 314300 | O13: 333.35914 | P13: 7000542 | Q13: =M13+O13 -> 348.32581 | R13: =P13+N13 -> 7314842
A14: 9 | B14: مهندس كهرباء وتحكم E2 | C14: عدد | D14: 19000 | E14: 2 | F14: 60 | G14: 120 | H14: 2280000 | I14: 3 | J14: 52.86 | K14: 158.58 | L14: 3013020 | M14: 1 | N14: =D14*M14 -> 19000 | O14: 25.51172 | P14: 484722.69 | Q14: =M14+O14 -> 26.51172 | R14: =P14+N14 -> 503722.69
A15: 10 | B15: مهندس كهرباء وتحكم E3 | C15: عدد | D15: 21000 | E15: 5 | F15: 60 | G15: 300 | H15: 6300000 | I15: 14 | J15: 52.86 | K15: 740.04 | L15: 15540840 | M15: 14.833333 | N15: =D15*M15 -> 311500 | O15: 295.47319 | P15: 6204937 | Q15: =M15+O15 -> 310.30652 | R15: =P15+N15 -> 6516437
A16: 11 | B16: مهندس أمن وسلامة E2 | C16: عدد | D16: 18000 | E16: 2 | F16: 60 | G16: 120 | H16: 2160000 | I16: 4 | J16: 52.86 | K16: 211.44 | L16: 3805920 | M16: 3 | N16: =D16*M16 -> 54000 | O16: 109.09944 | P16: 1963789.9 | Q16: =M16+O16 -> 112.09944 | R16: =P16+N16 -> 2017789.9
A17: 12 | B17: مهندس أمن وسلامة E3 | C17: عدد | D17: 21000 | E17: 5 | F17: 60 | G17: 300 | H17: 6300000 | I17: 11 | J17: 52.86 | K17: 581.46 | L17: 12210660 | M17: 10.466667 | N17: =D17*M17 -> 219800 | O17: 219.09968 | P17: 4601093.2 | Q17: =M17+O17 -> 229.56634 | R17: =P17+N17 -> 4820893.2
... A25: 20 | B25: مهندس كيميائي E3 | C25: عدد | D25: 23000 | E25: 1 | F25: 60 | G25: 60 | H25: 1380000 | I25: 0 | J25: 52.86 | K25: 0 | L25: 0 | M25: 0 | N25: =D25*M25 -> 0 | O25: 0 | P25: 0 | Q25: =M25+O25 -> 0 | R25: =P25+N25 -> 0
A26: 21 | B26: حاسب كميات E2 | C26: عدد | D26: 15000 | E26: 1 | F26: 60 | H26: 900000 | I26: 4 | J26: 52.86 | L26: 3171600 | M26: 6.7 | N26: =D26*M26 -> 100500 | O26: 192.67556 | P26: 2890133.5 | Q26: =M26+O26 -> 199.37556 | R26: =P26+N26 -> 2990633.5
A27: 22 | B27: حاسب كميات E3 | C27: عدد | D27: 17000 | E27: 2 | F27: 60 | H27: 2040000 | I27: 14 | J27: 52.86 | L27: 12580680 | M27: 23.633333 | N27: =D27*M27 -> 401766.67 | O27: 437.47146 | P27: 7437014.8 | Q27: =M27+O27 -> 461.10479 | R27: =P27+N27 -> 7838781.4
A28: 23 | B28: مراقب موقع E2 | C28: عدد | D28: 12000 | E28: 7 | F28: 60 | H28: 5040000 | I28: 16 | J28: 52.86 | L28: 10149120 | M28: 23.833333 | N28: =D28*M28 -> 286000 | O28: 535.16259 | P28: 6421951.1 | Q28: =M28+O28 -> 558.99593 | R28: =P28+N28 -> 6707951.1
A29: 24 | B29: مراقب موقع E3 | C29: عدد | D29: 12000 | E29: 25 | F29: 60 | G29: 1500 | H29: 18000000 | I29: 74 | J29: 52.86 | K29: 3911.64 | L29: 46939680 | M29: 98.433333 | N29: =D29*M29 -> 1181200 | O29: 1847.2631 | P29: 22167157 | Q29: =M29+O29 -> 1945.6964 | R29: =P29+N29 -> 23348357
A30: 25 | B30: مساح E2 | C30: عدد | D30: 11000 | E30: 2 | F30: 60 | H30: 1320000 | I30: 4 | J30: 52.86 | L30: 2325840 | M30: 3.8333333 | N30: =D30*M30 -> 42166.667 | O30: 103.07246 | P30: 1133797.1 | Q30: =M30+O30 -> 106.9058 | R30: =P30+N30 -> 1175963.7
A31: 26 | B31: مساح E3 | C31: عدد | D31: 13000 | E31: 7 | F31: 60 | H31: 5460000 | I31: 50 | J31: 52.86 | L31: 34359000 | M31: 86.333333 | N31: =D31*M31 -> 1122333.3 | O31: 1671.7829 | P31: 21733178 | Q31: =M31+O31 -> 1758.1163 | R31: =P31+N31 -> 22855511
A32: 27 | B32: مراقب أمن وسلامة E2 | C32: عدد | D32: 11000 | E32: 2 | F32: 60 | H32: 1320000 | I32: 16 | J32: 52.86 | L32: 9303360 | M32: 25.733333 | N32: =D32*M32 -> 283066.67 | O32: 541.40447 | P32: 5955449.1 | Q32: =M32+O32 -> 567.1378 | R32: =P32+N32 -> 6238515.8
A33: 28 | B33: مراقب أمن وسلامة E3 | C33: عدد | D33: 12000 | E33: 8 | F33: 60 | H33: 5760000 | I33: 26 | J33: 52.86 | L33: 16492320 | M33: 34.866667 | N33: =D33*M33 -> 418400 | O33: 552.37462 | P33: 6628495.5 | Q33: =M33+O33 -> 587.24129 | R33: =P33+N33 -> 7046895.5
A34: 29 | B34: أخصائي وثائق E2 | C34: عدد | D34: 10000 | E34: 1 | F34: 60 | G34: 60 | H34: 600000 | I34: 10 | J34: 52.86 | K34: 528.6 | L34: 5286000 | M34: 25.533333 | N34: =D34*M34 -> 255333.33 | O34: 545.18364 | P34: 5451836.4 | Q34: =M34+O34 -> 570.71697 | R34: =P34+N34 -> 5707169.7
A35: 30 | B35: أخصائي وثائق E3 | C35: عدد | D35: 10000 | E35: 3 | F35: 60 | G35: 180 | H35: 1800000 | I35: 9.4076788 | J35: 52.86 | K35: 497.2899 | L35: 4972899 | M35: 14.2 | N35: =D35*M35 -> 142000 | O35: 333.46436 | P35: 3334643.6 | Q35: =M35+O35 -> 347.66436 | R35: =P35+N35 -> 3476643.6
A36: الإجمـــــــــــــــــــــــــــــالي | I36: =SUM(I6:I35) -> 357.90768 | K36: =SUM(K6:K35) -> 12047.2 | L36: =SUM(L6:L35) -> 305111979 | N36: =SUM(N6:N35) -> 7644166.7 | P36: =SUM(P6:P35) -> 1.6051569e+08 | R36: =SUM(R6:R35) -> 1.6815985e+08
A37: قيمة الضريبة المضافة | L37: =L36*0.15 -> 45766797 | N37: =N36*0.15 -> 1146625 | P37: =P36*0.15 -> 24077353 | R37: =R36*0.15 -> 25223978
A38: الإجمـــــــــــــــــــــــــــــالي بعد اضافة 15% قيمة مضافة | L38: =L36+L37 -> 3.5087878e+08 | N38: =N36+N37 -> 8790791.7 | P38: =P36+P37 -> 1.8459304e+08 | R38: =R36+R37 -> 1.9338383e+08
A39: نسبة المستحق لاجمالي العقد | N39: =N36/L36 -> 0.025053643 | P39: 0.23952879 | R39: =R36/L36 -> 0.55114143

Sheet 31
I1: ملخص المستخلص رقم (31)
B2: القطاع الجنوبي | I2: عن الفترة مـن 2026/3/01م حتى 2026/3/31 | O2: مدة العقد =60 شهر ميلادي | Q2: رقم العقد = 101230258
C3: مشروع : إتفاقية الخدمات الهندسية والإستشارية لتقديم خدمات الإشراف على تنفيذ مشاريع المياه والصرف الصحي بالقطاع الجنوبي | O3: قيمة العقد الأساسية = 126,000,000 ريال | Q3: قيمة العقد المعدلة المعتمدة = 305,111,979 ريال
A4: م | B4: الوصف | C4: الوحدة | D4: السعر الافرادي | E4: العقد الاساسي | I4: الجدول المعدل رقم (1) | M4: المستحق عن الفترة | O4: السابق | Q4: الاجمالي
E5: الكمية | F5: المدة | H5: المبلغ الاجمالي | I5: الكمية | J5: المدة | L5: المبلغ الاجمالي | M5: المدة الاجمالية لفترة المستحلص | N5: المبلغ الاجمالي لفترة المستخلص | O5: المدة الاجمالية السابقة (شهر) | P5: المبلغ الاجمالي السابق | Q5: اجمالي المدة | R5: المبلغ الاجمالي
A6: 1 | B6: مدير المشروع | C6: عدد | D6: 50000 | E6: 1 | F6: 60 | G6: 60 | H6: 3000000 | I6: 1.5 | J6: 52.86 | K6: 79.29 | L6: 3964500 | M6: 0.74193548 | N6: =D6*M6 -> 37096.774 | O6: 39.656068 | P6: 1982803.4 | Q6: =M6+O6 -> 40.398003 | R6: =P6+N6 -> 2019900.2
A7: 2 | B7: مهندس مقيم E1 | C7: عدد | D7: 45000 | E7: 1 | F7: 60 | G7: 60 | H7: 2700000 | I7: 0 | J7: 52.86 | K7: 0 | L7: 0 | M7: 0 | N7: =D7*M7 -> 0 | O7: 0 | P7: 0 | Q7: =M7+O7 -> 0 | R7: =P7+N7 -> 0
A8: 3 | B8: مهندس مقيم E2 | C8: عدد | D8: 23000 | E8: 2 | F8: 60 | G8: 120 | H8: 2760000 | I8: 0 | J8: 52.86 | K8: 0 | L8: 0 | M8: 0 | N8: =D8*M8 -> 0 | O8: 0 | P8: 0 | Q8: =M8+O8 -> 0 | R8: =P8+N8 -> 0
A9: 4 | B9: مهندس مقيم E3 | C9: عدد | D9: 28000 | E9: 7 | F9: 60 | G9: 420 | H9: 11760000 | I9: 23 | J9: 52.86 | K9: 1215.78 | L9: 34041840 | M9: 31.354839 | N9: =D9*M9 -> 877935.48 | O9: 696.38991 | P9: 19498918 | Q9: =M9+O9 -> 727.74475 | R9: =P9+N9 -> 20376853
A10: 5 | B10: مهندس موقع E2 | C10: عدد | D10: 19000 | E10: 3 | F10: 60 | G10: 180 | H10: 3420000 | I10: 4 | J10: 52.86 | K10: 211.44 | L10: 4017360 | M10: 2.8709677 | N10: =D10*M10 -> 54548.387 | O10: 48.704559 | P10: 925386.62 | Q10: =M10+O10 -> 51.575527 | R10: =P10+N10 -> 979935.01
A11: 6 | B11: مهندس موقع E3 | C11: عدد | D11: 21000 | E11: 15 | F11: 60 | G11: 900 | H11: 18900000 | I11: 47 | J11: 52.86 | K11: 2484.42 | L11: 52172820 | M11: 60.870968 | N11: =D11*M11 -> 1278290.3 | O11: 1301.9427 | P11: 27340797 | Q11: =M11+O11 -> 1362.8137 | R11: =P11+N11 -> 28619087
A12: 7 | B12: مهندس ميكانيكا E2 | C12: عدد | D12: 19000 | E12: 2 | F12: 60 | G12: 120 | H12: 2280000 | I12: 3 | J12: 52.86 | K12: 158.58 | L12: 3013020 | M12: 1 | N12: =D12*M12 -> 19000 | O12: 30.146633 | P12: 572786.03 | Q12: =M12+O12 -> 31.146633 | R12: =P12+N12 -> 591786.03
A13: 8 | B13: مهندس ميكانيكا E3 | C13: عدد | D13: 21000 | E13: 6 | F13: 60 | G13: 360 | H13: 7560000 | I13: 15 | J13: 52.86 | K13: 792.9 | L13: 16650900 | M13: 14.225806 | N13: =D13*M13 -> 298741.94 | O13: 319.13334 | P13: 6701800.1 | Q13: =M13+O13 -> 333.35914 | R13: =P13+N13 -> 7000542
A14: 9 | B14: مهندس كهرباء وتحكم E2 | C14: عدد | D14: 19000 | E14: 2 | F14: 60 | G14: 120 | H14: 2280000 | I14: 3 | J14: 52.86 | K14: 158.58 | L14: 3013020 | M14: 0.87096774 | N14: =D14*M14 -> 16548.387 | O14: 24.640753 | P14: 468174.3 | Q14: =M14+O14 -> 25.51172 | R14: =P14+N14 -> 484722.69
A15: 10 | B15: مهندس كهرباء وتحكم E3 | C15: عدد | D15: 21000 | E15: 5 | F15: 60 | G15: 300 | H15: 6300000 | I15: 14 | J15: 52.86 | K15: 740.04 | L15: 15540840 | M15: 15.677419 | N15: =D15*M15 -> 329225.81 | O15: 279.79577 | P15: 5875711.2 | Q15: =M15+O15 -> 295.47319 | R15: =P15+N15 -> 6204937
A16: 11 | B16: مهندس أمن وسلامة E2 | C16: عدد | D16: 18000 | E16: 2 | F16: 60 | G16: 120 | H16: 2160000 | I16: 4 | J16: 52.86 | K16: 211.44 | L16: 3805920 | M16: 3 | N16: =D16*M16 -> 54000 | O16: 106.09944 | P16: 1909789.9 | Q16: =M16+O16 -> 109.09944 | R16: =P16+N16 -> 1963789.9
A17: 12 | B17: مهندس أمن وسلامة E3 | C17: عدد | D17: 21000 | E17: 5 | F17: 60 | G17: 300 | H17: 6300000 | I17: 11 | J17: 52.86 | K17: 581.46 | L17: 12210660 | M17: 10.903226 | N17: =D17*M17 -> 228967.74 | O17: 208.19645 | P17: 4372125.5 | Q17: =M17+O17 -> 219.09968 | R17: =P17+N17 -> 4601093.2
... A25: 20 | B25: مهندس كيميائي E3 | C25: عدد | D25: 23000 | E25: 1 | F25: 60 | G25: 60 | H25: 1380000 | I25: 0 | J25: 52.86 | K25: 0 | L25: 0 | M25: 0 | N25: =D25*M25 -> 0 | O25: 0 | P25: 0 | Q25: =M25+O25 -> 0 | R25: =P25+N25 -> 0
A26: 21 | B26: حاسب كميات E2 | C26: عدد | D26: 15000 | E26: 1 | F26: 60 | H26: 900000 | I26: 4 | J26: 52.86 | L26: 3171600 | M26: 6.9354839 | N26: =D26*M26 -> 104032.26 | O26: 185.74008 | P26: 2786101.2 | Q26: =M26+O26 -> 192.67556 | R26: =P26+N26 -> 2890133.5
A27: 22 | B27: حاسب كميات E3 | C27: عدد | D27: 17000 | E27: 2 | F27: 60 | H27: 2040000 | I27: 14 | J27: 52.86 | L27: 12580680 | M27: 24.258065 | N27: =D27*M27 -> 412387.1 | O27: 413.21339 | P27: 7024627.7 | Q27: =M27+O27 -> 437.47146 | R27: =P27+N27 -> 7437014.8
A28: 23 | B28: مراقب موقع E2 | C28: عدد | D28: 12000 | E28: 7 | F28: 60 | H28: 5040000 | I28: 16 | J28: 52.86 | L28: 10149120 | M28: 23.16129 | N28: =D28*M28 -> 277935.48 | O28: 512.0013 | P28: 6144015.6 | Q28: =M28+O28 -> 535.16259 | R28: =P28+N28 -> 6421951.1
A29: 24 | B29: مراقب موقع E3 | C29: عدد | D29: 12000 | E29: 25 | F29: 60 | G29: 1500 | H29: 18000000 | I29: 74 | J29: 52.86 | K29: 3911.64 | L29: 46939680 | M29: 95.290323 | N29: =D29*M29 -> 1143483.9 | O29: 1751.9728 | P29: 21023673 | Q29: =M29+O29 -> 1847.2631 | R29: =P29+N29 -> 22167157
A30: 25 | B30: مساح E2 | C30: عدد | D30: 11000 | E30: 2 | F30: 60 | H30: 1320000 | I30: 4 | J30: 52.86 | L30: 2325840 | M30: 4 | N30: =D30*M30 -> 44000 | O30: 99.072462 | P30: 1089797.1 | Q30: =M30+O30 -> 103.07246 | R30: =P30+N30 -> 1133797.1
A31: 26 | B31: مساح E3 | C31: عدد | D31: 13000 | E31: 7 | F31: 60 | H31: 5460000 | I31: 50 | J31: 52.86 | L31: 34359000 | M31: 85.935484 | N31: =D31*M31 -> 1117161.3 | O31: 1585.8474 | P31: 20616017 | Q31: =M31+O31 -> 1671.7829 | R31: =P31+N31 -> 21733178
A32: 27 | B32: مراقب أمن وسلامة E2 | C32: عدد | D32: 11000 | E32: 2 | F32: 60 | H32: 1320000 | I32: 16 | J32: 52.86 | L32: 9303360 | M32: 26.193548 | N32: =D32*M32 -> 288129.03 | O32: 515.21092 | P32: 5667320.1 | Q32: =M32+O32 -> 541.40447 | R32: =P32+N32 -> 5955449.1
A33: 28 | B33: مراقب أمن وسلامة E3 | C33: عدد | D33: 12000 | E33: 8 | F33: 60 | H33: 5760000 | I33: 26 | J33: 52.86 | L33: 16492320 | M33: 34.16129 | N33: =D33*M33 -> 409935.48 | O33: 518.21333 | P33: 6218560 | Q33: =M33+O33 -> 552.37462 | R33: =P33+N33 -> 6628495.5
A34: 29 | B34: أخصائي وثائق E2 | C34: عدد | D34: 10000 | E34: 1 | F34: 60 | G34: 60 | H34: 600000 | I34: 10 | J34: 52.86 | K34: 528.6 | L34: 5286000 | M34: 25.645161 | N34: =D34*M34 -> 256451.61 | O34: 519.53848 | P34: 5195384.8 | Q34: =M34+O34 -> 545.18364 | R34: =P34+N34 -> 5451836.4
A35: 30 | B35: أخصائي وثائق E3 | C35: عدد | D35: 10000 | E35: 3 | F35: 60 | G35: 180 | H35: 1800000 | I35: 9.4076788 | J35: 52.86 | K35: 497.2899 | L35: 4972899 | M35: 13.967742 | N35: =D35*M35 -> 139677.42 | O35: 319.49662 | P35: 3194966.2 | Q35: =M35+O35 -> 333.46436 | R35: =P35+N35 -> 3334643.6
A36: الإجمـــــــــــــــــــــــــــــالي | H36: =SUM(H6:H35) -> 126000000 | K36: =SUM(K6:K35) -> 12047.2 | L36: =SUM(L6:L35) -> 305111979 | N36: =SUM(N6:N35) -> 7623548.4 | P36: =SUM(P6:P35) -> 1.5289214e+08 | R36: =SUM(R6:R35) -> 1.6051569e+08
A37: قيمة الضريبة المضافة | L37: =L36*0.15 -> 45766797 | N37: =N36*0.15 -> 1143532.3 | P37: =P36*0.15 -> 22933821 | R37: =R36*0.15 -> 24077353
A38: الإجمـــــــــــــــــــــــــــــالي بعد اضافة 15% قيمة مضافة | L38: =L36+L37 -> 3.5087878e+08 | N38: =N36+N37 -> 8767080.6 | P38: =P36+P37 -> 1.7582596e+08 | R38: =R36+R37 -> 1.8459304e+08
A39: نسبة المستحق لاجمالي العقد | N39: =N36/L36 -> 0.024986067 | P39: 0.23952879 | R39: =R36/L36 -> 0.52608779

Sheet 30
I1: ملخص المستخلص رقم (30)
B2: القطاع الجنوبي | I2: عن الفترة مـن 2026/2/01م حتى 2026/2/28 | O2: مدة العقد =60 شهر ميلادي | Q2: رقم العقد = 101230258
C3: مشروع : إتفاقية الخدمات الهندسية والإستشارية لتقديم خدمات الإشراف على تنفيذ مشاريع المياه والصرف الصحي بالقطاع الجنوبي | O3: قيمة العقد الأساسية = 126,000,000 ريال | Q3: قيمة العقد المعدلة المعتمدة = 305,111,979 ريال
A4: م | B4: الوصف | C4: الوحدة | D4: السعر الافرادي | E4: العقد الاساسي | I4: الجدول المعدل رقم (1) | M4: المستحق عن الفترة | O4: السابق | Q4: الاجمالي
E5: الكمية | F5: المدة | H5: المبلغ الاجمالي | I5: الكمية | J5: المدة | L5: المبلغ الاجمالي | M5: المدة الاجمالية لفترة المستحلص | N5: المبلغ الاجمالي لفترة المستخلص | O5: المدة الاجمالية السابقة (شهر) | P5: المبلغ الاجمالي السابق | Q5: اجمالي المدة | R5: المبلغ الاجمالي
A6: 1 | B6: مدير المشروع | C6: عدد | D6: 50000 | E6: 1 | F6: 60 | G6: 60 | H6: 3000000 | I6: 1.5 | J6: 52.86 | K6: 79.29 | L6: 3964500 | M6: 0.85714286 | N6: =D6*M6 -> 42857.143 | O6: 38.798925 | P6: 1939946.2 | Q6: =M6+O6 -> 39.656068 | R6: =P6+N6 -> 1982803.4
A7: 2 | B7: مهندس مقيم E1 | C7: عدد | D7: 45000 | E7: 1 | F7: 60 | G7: 60 | H7: 2700000 | I7: 0 | J7: 52.86 | K7: 0 | L7: 0 | M7: 0 | N7: =D7*M7 -> 0 | O7: 0 | P7: 0 | Q7: =M7+O7 -> 0 | R7: =P7+N7 -> 0
A8: 3 | B8: مهندس مقيم E2 | C8: عدد | D8: 23000 | E8: 2 | F8: 60 | G8: 120 | H8: 2760000 | I8: 0 | J8: 52.86 | K8: 0 | L8: 0 | M8: 0 | N8: =D8*M8 -> 0 | O8: 0 | P8: 0 | Q8: =M8+O8 -> 0 | R8: =P8+N8 -> 0
A9: 4 | B9: مهندس مقيم E3 | C9: عدد | D9: 28000 | E9: 7 | F9: 60 | G9: 420 | H9: 11760000 | I9: 23 | J9: 52.86 | K9: 1215.78 | L9: 34041840 | M9: 31.571429 | N9: =D9*M9 -> 884000 | O9: 664.81848 | P9: 18614918 | Q9: =M9+O9 -> 696.38991 | R9: =P9+N9 -> 19498918
A10: 5 | B10: مهندس موقع E2 | C10: عدد | D10: 19000 | E10: 3 | F10: 60 | G10: 180 | H10: 3420000 | I10: 4 | J10: 52.86 | K10: 211.44 | L10: 4017360 | M10: 2.8571429 | N10: =D10*M10 -> 54285.714 | O10: 45.847416 | P10: 871100.91 | Q10: =M10+O10 -> 48.704559 | R10: =P10+N10 -> 925386.62
A11: 6 | B11: مهندس موقع E3 | C11: عدد | D11: 21000 | E11: 15 | F11: 60 | G11: 900 | H11: 18900000 | I11: 47 | J11: 52.86 | K11: 2484.42 | L11: 52172820 | M11: 62.392857 | N11: =D11*M11 -> 1310250 | O11: 1239.5498 | P11: 26030547 | Q11: =M11+O11 -> 1301.9427 | R11: =P11+N11 -> 27340797
A12: 7 | B12: مهندس ميكانيكا E2 | C12: عدد | D12: 19000 | E12: 2 | F12: 60 | G12: 120 | H12: 2280000 | I12: 3 | J12: 52.86 | K12: 158.58 | L12: 3013020 | M12: 1 | N12: =D12*M12 -> 19000 | O12: 29.146633 | P12: 553786.03 | Q12: =M12+O12 -> 30.146633 | R12: =P12+N12 -> 572786.03
A13: 8 | B13: مهندس ميكانيكا E3 | C13: عدد | D13: 21000 | E13: 6 | F13: 60 | G13: 360 | H13: 7560000 | I13: 15 | J13: 52.86 | K13: 792.9 | L13: 16650900 | M13: 14.607143 | N13: =D13*M13 -> 306750 | O13: 304.52619 | P13: 6395050.1 | Q13: =M13+O13 -> 319.13334 | R13: =P13+N13 -> 6701800.1
A14: 9 | B14: مهندس كهرباء وتحكم E2 | C14: عدد | D14: 19000 | E14: 2 | F14: 60 | G14: 120 | H14: 2280000 | I14: 3 | J14: 52.86 | K14: 158.58 | L14: 3013020 | M14: 1 | N14: =D14*M14 -> 19000 | O14: 23.640753 | P14: 449174.3 | Q14: =M14+O14 -> 24.640753 | R14: =P14+N14 -> 468174.3
A15: 10 | B15: مهندس كهرباء وتحكم E3 | C15: عدد | D15: 21000 | E15: 5 | F15: 60 | G15: 300 | H15: 6300000 | I15: 14 | J15: 52.86 | K15: 740.04 | L15: 15540840 | M15: 15.857143 | N15: =D15*M15 -> 333000 | O15: 263.93863 | P15: 5542711.2 | Q15: =M15+O15 -> 279.79577 | R15: =P15+N15 -> 5875711.2
A16: 11 | B16: مهندس أمن وسلامة E2 | C16: عدد | D16: 18000 | E16: 2 | F16: 60 | G16: 120 | H16: 2160000 | I16: 4 | J16: 52.86 | K16: 211.44 | L16: 3805920 | M16: 3 | N16: =D16*M16 -> 54000 | O16: 103.09944 | P16: 1855789.9 | Q16: =M16+O16 -> 106.09944 | R16: =P16+N16 -> 1909789.9
A17: 12 | B17: مهندس أمن وسلامة E3 | C17: عدد | D17: 21000 | E17: 5 | F17: 60 | G17: 300 | H17: 6300000 | I17: 11 | J17: 52.86 | K17: 581.46 | L17: 12210660 | M17: 10.392857 | N17: =D17*M17 -> 218250 | O17: 197.80359 | P17: 4153875.5 | Q17: =M17+O17 -> 208.19645 | R17: =P17+N17 -> 4372125.5
... A25: 20 | B25: مهندس كيميائي E3 | C25: عدد | D25: 23000 | E25: 1 | F25: 60 | G25: 60 | H25: 1380000 | I25: 0 | J25: 52.86 | K25: 0 | L25: 0 | M25: 0 | N25: =D25*M25 -> 0 | O25: 0 | P25: 0 | Q25: =M25+O25 -> 0 | R25: =P25+N25 -> 0
A26: 21 | B26: حاسب كميات E2 | C26: عدد | D26: 15000 | E26: 1 | F26: 60 | H26: 900000 | I26: 4 | J26: 52.86 | L26: 3171600 | M26: 7.8214286 | N26: =D26*M26 -> 117321.43 | O26: 177.91865 | P26: 2668779.8 | Q26: =M26+O26 -> 185.74008 | R26: =P26+N26 -> 2786101.2
A27: 22 | B27: حاسب كميات E3 | C27: عدد | D27: 17000 | E27: 2 | F27: 60 | H27: 2040000 | I27: 14 | J27: 52.86 | L27: 12580680 | M27: 24.964286 | N27: =D27*M27 -> 424392.86 | O27: 388.24911 | P27: 6600234.8 | Q27: =M27+O27 -> 413.21339 | R27: =P27+N27 -> 7024627.7
A28: 23 | B28: مراقب موقع E2 | C28: عدد | D28: 12000 | E28: 7 | F28: 60 | H28: 5040000 | I28: 16 | J28: 52.86 | L28: 10149120 | M28: 23.107143 | N28: =D28*M28 -> 277285.71 | O28: 488.89416 | P28: 5866729.9 | Q28: =M28+O28 -> 512.0013 | R28: =P28+N28 -> 6144015.6
A29: 24 | B29: مراقب موقع E3 | C29: عدد | D29: 12000 | E29: 25 | F29: 60 | G29: 1500 | H29: 18000000 | I29: 74 | J29: 52.86 | K29: 3911.64 | L29: 46939680 | M29: 99 | N29: =D29*M29 -> 1188000 | O29: 1652.9728 | P29: 19835673 | Q29: =M29+O29 -> 1751.9728 | R29: =P29+N29 -> 21023673
A30: 25 | B30: مساح E2 | C30: عدد | D30: 11000 | E30: 2 | F30: 60 | H30: 1320000 | I30: 4 | J30: 52.86 | L30: 2325840 | M30: 3.7857143 | N30: =D30*M30 -> 41642.857 | O30: 95.286747 | P30: 1048154.2 | Q30: =M30+O30 -> 99.072462 | R30: =P30+N30 -> 1089797.1
A31: 26 | B31: مساح E3 | C31: عدد | D31: 13000 | E31: 7 | F31: 60 | H31: 5460000 | I31: 50 | J31: 52.86 | L31: 34359000 | M31: 87.678571 | N31: =D31*M31 -> 1139821.4 | O31: 1498.1689 | P31: 19476195 | Q31: =M31+O31 -> 1585.8474 | R31: =P31+N31 -> 20616017
A32: 27 | B32: مراقب أمن وسلامة E2 | C32: عدد | D32: 11000 | E32: 2 | F32: 60 | H32: 1320000 | I32: 16 | J32: 52.86 | L32: 9303360 | M32: 26.107143 | N32: =D32*M32 -> 287178.57 | O32: 489.10378 | P32: 5380141.5 | Q32: =M32+O32 -> 515.21092 | R32: =P32+N32 -> 5667320.1
A33: 28 | B33: مراقب أمن وسلامة E3 | C33: عدد | D33: 12000 | E33: 8 | F33: 60 | H33: 5760000 | I33: 26 | J33: 52.86 | L33: 16492320 | M33: 35 | N33: =D33*M33 -> 420000 | O33: 483.21333 | P33: 5798560 | Q33: =M33+O33 -> 518.21333 | R33: =P33+N33 -> 6218560
A34: 29 | B34: أخصائي وثائق E2 | C34: عدد | D34: 10000 | E34: 1 | F34: 60 | G34: 60 | H34: 600000 | I34: 10 | J34: 52.86 | K34: 528.6 | L34: 5286000 | M34: 25.214286 | N34: =D34*M34 -> 252142.86 | O34: 494.32419 | P34: 4943241.9 | Q34: =M34+O34 -> 519.53848 | R34: =P34+N34 -> 5195384.8
A35: 30 | B35: أخصائي وثائق E3 | C35: عدد | D35: 10000 | E35: 3 | F35: 60 | G35: 180 | H35: 1800000 | I35: 9.4076788 | J35: 52.86 | K35: 497.2899 | L35: 4972899 | M35: 15.464286 | N35: =D35*M35 -> 154642.86 | O35: 304.03233 | P35: 3040323.3 | Q35: =M35+O35 -> 319.49662 | R35: =P35+N35 -> 3194966.2
A36: الإجمـــــــــــــــــــــــــــــالي | H36: =SUM(H6:H35) -> 126000000 | K36: =SUM(K6:K35) -> 12047.2 | L36: =SUM(L6:L35) -> 305111979 | N36: =SUM(N6:N35) -> 7779821.4 | P36: =SUM(P6:P35) -> 1.4511232e+08 | R36: =SUM(R6:R35) -> 1.5289214e+08
A37: قيمة الضريبة المضافة | L37: =L36*0.15 -> 45766797 | N37: =N36*0.15 -> 1166973.2 | P37: =P36*0.15 -> 21766848 | R37: =R36*0.15 -> 22933821
A38: الإجمـــــــــــــــــــــــــــــالي بعد اضافة 15% قيمة مضافة | L38: =L36+L37 -> 3.5087878e+08 | N38: =N36+N37 -> 8946794.6 | P38: =P36+P37 -> 1.6687916e+08 | R38: =R36+R37 -> 1.7582596e+08
A39: نسبة المستحق لاجمالي العقد | N39: =N36/L36 -> 0.02549825 | P39: 0.23952879 | R39: =R36/L36 -> 0.50110172

Sheet 29
I1: ملخص المستخلص رقم (29)
B2: القطاع الجنوبي | I2: عن الفترة مـن 2026/1/01م حتى 2026/1/31 | O2: مدة العقد =60 شهر ميلادي | Q2: رقم العقد = 101230258
C3: مشروع : إتفاقية الخدمات الهندسية والإستشارية لتقديم خدمات الإشراف على تنفيذ مشاريع المياه والصرف الصحي بالقطاع الجنوبي | O3: قيمة العقد الأساسية = 126,000,000 ريال | Q3: قيمة العقد المعدلة المعتمدة = 305,111,979 ريال
A4: م | B4: الوصف | C4: الوحدة | D4: السعر الافرادي | E4: العقد الاساسي | I4: الجدول المعدل رقم (1) | M4: المستحق عن الفترة | O4: السابق | Q4: الاجمالي
E5: الكمية | F5: المدة | H5: المبلغ الاجمالي | I5: الكمية | J5: المدة | L5: المبلغ الاجمالي | M5: المدة الاجمالية لفترة المستحلص | N5: المبلغ الاجمالي لفترة المستخلص | O5: المدة الاجمالية السابقة (شهر) | P5: المبلغ الاجمالي السابق | Q5: اجمالي المدة | R5: المبلغ الاجمالي
A6: 1 | B6: مدير المشروع | C6: عدد | D6: 50000 | E6: 1 | F6: 60 | G6: 60 | H6: 3000000 | I6: 1.5 | J6: 52.86 | K6: 79.29 | L6: 3964500 | M6: 1 | N6: =D6*M6 -> 50000 | O6: 37.798925 | P6: 1889946.2 | Q6: =M6+O6 -> 38.798925 | R6: =P6+N6 -> 1939946.2
A7: 2 | B7: مهندس مقيم E1 | C7: عدد | D7: 45000 | E7: 1 | F7: 60 | G7: 60 | H7: 2700000 | I7: 0 | J7: 52.86 | K7: 0 | L7: 0 | M7: 0 | N7: =D7*M7 -> 0 | O7: 0 | P7: 0 | Q7: =M7+O7 -> 0 | R7: =P7+N7 -> 0
A8: 3 | B8: مهندس مقيم E2 | C8: عدد | D8: 23000 | E8: 2 | F8: 60 | G8: 120 | H8: 2760000 | I8: 0 | J8: 52.86 | K8: 0 | L8: 0 | M8: 0 | N8: =D8*M8 -> 0 | O8: 0 | P8: 0 | Q8: =M8+O8 -> 0 | R8: =P8+N8 -> 0
A9: 4 | B9: مهندس مقيم E3 | C9: عدد | D9: 28000 | E9: 7 | F9: 60 | G9: 420 | H9: 11760000 | I9: 23 | J9: 52.86 | K9: 1215.78 | L9: 34041840 | M9: 32.774194 | N9: =D9*M9 -> 917677.42 | O9: 632.04429 | P9: 17697240 | Q9: =M9+O9 -> 664.81848 | R9: =P9+N9 -> 18614918
A10: 5 | B10: مهندس موقع E2 | C10: عدد | D10: 19000 | E10: 3 | F10: 60 | G10: 180 | H10: 3420000 | I10: 4 | J10: 52.86 | K10: 211.44 | L10: 4017360 | M10: 3 | N10: =D10*M10 -> 57000 | O10: 42.847416 | P10: 814100.91 | Q10: =M10+O10 -> 45.847416 | R10: =P10+N10 -> 871100.91
A11: 6 | B11: مهندس موقع E3 | C11: عدد | D11: 21000 | E11: 15 | F11: 60 | G11: 900 | H11: 18900000 | I11: 47 | J11: 52.86 | K11: 2484.42 | L11: 52172820 | M11: 64.387097 | N11: =D11*M11 -> 1352129 | O11: 1175.1627 | P11: 24678418 | Q11: =M11+O11 -> 1239.5498 | R11: =P11+N11 -> 26030547
A12: 7 | B12: مهندس ميكانيكا E2 | C12: عدد | D12: 19000 | E12: 2 | F12: 60 | G12: 120 | H12: 2280000 | I12: 3 | J12: 52.86 | K12: 158.58 | L12: 3013020 | M12: 1 | N12: =D12*M12 -> 19000 | O12: 28.146633 | P12: 534786.03 | Q12: =M12+O12 -> 29.146633 | R12: =P12+N12 -> 553786.03
A13: 8 | B13: مهندس ميكانيكا E3 | C13: عدد | D13: 21000 | E13: 6 | F13: 60 | G13: 360 | H13: 7560000 | I13: 15 | J13: 52.86 | K13: 792.9 | L13: 16650900 | M13: 15.741935 | N13: =D13*M13 -> 330580.65 | O13: 288.78426 | P13: 6064469.4 | Q13: =M13+O13 -> 304.52619 | R13: =P13+N13 -> 6395050.1
A14: 9 | B14: مهندس كهرباء وتحكم E2 | C14: عدد | D14: 19000 | E14: 2 | F14: 60 | G14: 120 | H14: 2280000 | I14: 3 | J14: 52.86 | K14: 158.58 | L14: 3013020 | M14: 0.83870968 | N14: =D14*M14 -> 15935.484 | O14: 22.802043 | P14: 433238.82 | Q14: =M14+O14 -> 23.640753 | R14: =P14+N14 -> 449174.3
A15: 10 | B15: مهندس كهرباء وتحكم E3 | C15: عدد | D15: 21000 | E15: 5 | F15: 60 | G15: 300 | H15: 6300000 | I15: 14 | J15: 52.86 | K15: 740.04 | L15: 15540840 | M15: 15.258065 | N15: =D15*M15 -> 320419.35 | O15: 248.68056 | P15: 5222291.8 | Q15: =M15+O15 -> 263.93863 | R15: =P15+N15 -> 5542711.2
A16: 11 | B16: مهندس أمن وسلامة E2 | C16: عدد | D16: 18000 | E16: 2 | F16: 60 | G16: 120 | H16: 2160000 | I16: 4 | J16: 52.86 | K16: 211.44 | L16: 3805920 | M16: 3 | N16: =D16*M16 -> 54000 | O16: 100.09944 | P16: 1801789.9 | Q16: =M16+O16 -> 103.09944 | R16: =P16+N16 -> 1855789.9
A17: 12 | B17: مهندس أمن وسلامة E3 | C17: عدد | D17: 21000 | E17: 5 | F17: 60 | G17: 300 | H17: 6300000 | I17: 11 | J17: 52.86 | K17: 581.46 | L17: 12210660 | M17: 9.9354839 | N17: =D17*M17 -> 208645.16 | O17: 187.86811 | P17: 3945230.3 | Q17: =M17+O17 -> 197.80359 | R17: =P17+N17 -> 4153875.5
... A25: 20 | B25: مهندس كيميائي E3 | C25: عدد | D25: 23000 | E25: 1 | F25: 60 | G25: 60 | H25: 1380000 | I25: 0 | J25: 52.86 | K25: 0 | L25: 0 | M25: 0 | N25: =D25*M25 -> 0 | O25: 0 | P25: 0 | Q25: =M25+O25 -> 0 | R25: =P25+N25 -> 0
A26: 21 | B26: حاسب كميات E2 | C26: عدد | D26: 15000 | E26: 1 | F26: 60 | H26: 900000 | I26: 4 | J26: 52.86 | L26: 3171600 | M26: 8.1612903 | N26: =D26*M26 -> 122419.35 | O26: 169.75736 | P26: 2546360.4 | Q26: =M26+O26 -> 177.91865 | R26: =P26+N26 -> 2668779.8
A27: 22 | B27: حاسب كميات E3 | C27: عدد | D27: 17000 | E27: 2 | F27: 60 | H27: 2040000 | I27: 14 | J27: 52.86 | L27: 12580680 | M27: 25.548387 | N27: =D27*M27 -> 434322.58 | O27: 362.70072 | P27: 6165912.2 | Q27: =M27+O27 -> 388.24911 | R27: =P27+N27 -> 6600234.8
A28: 23 | B28: مراقب موقع E2 | C28: عدد | D28: 12000 | E28: 7 | F28: 60 | H28: 5040000 | I28: 16 | J28: 52.86 | L28: 10149120 | M28: 23.806452 | N28: =D28*M28 -> 285677.42 | O28: 465.08771 | P28: 5581052.5 | Q28: =M28+O28 -> 488.89416 | R28: =P28+N28 -> 5866729.9
A29: 24 | B29: مراقب موقع E3 | C29: عدد | D29: 12000 | E29: 25 | F29: 60 | G29: 1500 | H29: 18000000 | I29: 74 | J29: 52.86 | K29: 3911.64 | L29: 46939680 | M29: 100.54839 | N29: =D29*M29 -> 1206580.6 | O29: 1552.4244 | P29: 18629093 | Q29: =M29+O29 -> 1652.9728 | R29: =P29+N29 -> 19835673
A30: 25 | B30: مساح E2 | C30: عدد | D30: 11000 | E30: 2 | F30: 60 | H30: 1320000 | I30: 4 | J30: 52.86 | L30: 2325840 | M30: 4 | N30: =D30*M30 -> 44000 | O30: 91.286747 | P30: 1004154.2 | Q30: =M30+O30 -> 95.286747 | R30: =P30+N30 -> 1048154.2
A31: 26 | B31: مساح E3 | C31: عدد | D31: 13000 | E31: 7 | F31: 60 | H31: 5460000 | I31: 50 | J31: 52.86 | L31: 34359000 | M31: 89.096774 | N31: =D31*M31 -> 1158258.1 | O31: 1409.0721 | P31: 18317937 | Q31: =M31+O31 -> 1498.1689 | R31: =P31+N31 -> 19476195
A32: 27 | B32: مراقب أمن وسلامة E2 | C32: عدد | D32: 11000 | E32: 2 | F32: 60 | H32: 1320000 | I32: 16 | J32: 52.86 | L32: 9303360 | M32: 25.903226 | N32: =D32*M32 -> 284935.48 | O32: 463.20055 | P32: 5095206.1 | Q32: =M32+O32 -> 489.10378 | R32: =P32+N32 -> 5380141.5
A33: 28 | B33: مراقب أمن وسلامة E3 | C33: عدد | D33: 12000 | E33: 8 | F33: 60 | H33: 5760000 | I33: 26 | J33: 52.86 | L33: 16492320 | M33: 34.516129 | N33: =D33*M33 -> 414193.55 | O33: 448.69721 | P33: 5384366.5 | Q33: =M33+O33 -> 483.21333 | R33: =P33+N33 -> 5798560
A34: 29 | B34: أخصائي وثائق E2 | C34: عدد | D34: 10000 | E34: 1 | F34: 60 | G34: 60 | H34: 600000 | I34: 10 | J34: 52.86 | K34: 528.6 | L34: 5286000 | M34: 24.290323 | N34: =D34*M34 -> 242903.23 | O34: 470.03387 | P34: 4700338.7 | Q34: =M34+O34 -> 494.32419 | R34: =P34+N34 -> 4943241.9
A35: 30 | B35: أخصائي وثائق E3 | C35: عدد | D35: 10000 | E35: 3 | F35: 60 | G35: 180 | H35: 1800000 | I35: 9.4076788 | J35: 52.86 | K35: 497.2899 | L35: 4972899 | M35: 16.83871 | N35: =D35*M35 -> 168387.1 | O35: 287.19362 | P35: 2871936.2 | Q35: =M35+O35 -> 304.03233 | R35: =P35+N35 -> 3040323.3
